Workbook

Sheet Итоги
A1: Комната | B1: Итого, $ | C1: По рыночным ценам, $ | D1: Разница, $
A2: Анин гардероб | B2: =SUMPRODUCT((TRIM('B&B апрель 2025'!$A$2:$A$1311)=A2)*N(+'B&B апрель 2025'!$H$2:$H$1311)) -> 342.63705 | C2: =SUMPRODUCT((TRIM('B&B апрель 2025'!$A$2:$A$1311)=A2)*N(+'B&B апрель 2025'!$L$2:$L$1311)) -> 367.16061 | D2: =C2-B2 -> 24.52356
A3: Анина ванная | B3: =SUMPRODUCT((TRIM('B&B апрель 2025'!$A$2:$A$1311)=A3)*N(+'B&B апрель 2025'!$H$2:$H$1311)) -> 0 | C3: =SUMPRODUCT((TRIM('B&B апрель 2025'!$A$2:$A$1311)=A3)*N(+'B&B апрель 2025'!$L$2:$L$1311)) -> 0 | D3: =C3-B3 -> 0
A4: Анина спальня | B4: =SUMPRODUCT((TRIM('B&B апрель 2025'!$A$2:$A$1311)=A4)*N(+'B&B апрель 2025'!$H$2:$H$1311)) -> 245.115 | C4: =SUMPRODUCT((TRIM('B&B апрель 2025'!$A$2:$A$1311)=A4)*N(+'B&B апрель 2025'!$L$2:$L$1311)) -> 255.03899 | D4: =C4-B4 -> 9.9239908
A5: Мастер-спальня | B5: =SUMPRODUCT((TRIM('B&B апрель 2025'!$A$2:$A$1311)=A5)*N(+'B&B апрель 2025'!$H$2:$H$1311)) -> 172.9642 | C5: =SUMPRODUCT((TRIM('B&B апрель 2025'!$A$2:$A$1311)=A5)*N(+'B&B апрель 2025'!$L$2:$L$1311)) -> 172.9642 | D5: =C5-B5 -> 0
A6: Мастер спальня | B6: =SUMPRODUCT((TRIM('B&B апрель 2025'!$A$2:$A$1311)=A6)*N(+'B&B апрель 2025'!$H$2:$H$1311)) -> 9.5 | C6: =SUMPRODUCT((TRIM('B&B апрель 2025'!$A$2:$A$1311)=A6)*N(+'B&B апрель 2025'!$L$2:$L$1311)) -> 9.5 | D6: =C6-B6 -> 0
A7: Часовня | B7: =SUMPRODUCT((TRIM('B&B апрель 2025'!$A$2:$A$1311)=A7)*N(+'B&B апрель 2025'!$H$2:$H$1311)) -> 775.4622 | C7: =SUMPRODUCT((TRIM('B&B апрель 2025'!$A$2:$A$1311)=A7)*N(+'B&B апрель 2025'!$L$2:$L$1311)) -> 842.66269 | D7: =C7-B7 -> 67.20049
A8: Балка часовня | B8: =SUMPRODUCT((TRIM('B&B апрель 2025'!$A$2:$A$1311)=A8)*N(+'B&B апрель 2025'!$H$2:$H$1311)) -> 26.5093 | C8: =SUMPRODUCT((TRIM('B&B апрель 2025'!$A$2:$A$1311)=A8)*N(+'B&B апрель 2025'!$L$2:$L$1311)) -> 31.562183 | D8: =C8-B8 -> 5.0528832
A9: Фойе 2 эт | B9: =SUMPRODUCT((TRIM('B&B апрель 2025'!$A$2:$A$1311)=A9)*N(+'B&B апрель 2025'!$H$2:$H$1311)) -> 284.29715 | C9: =SUMPRODUCT((TRIM('B&B апрель 2025'!$A$2:$A$1311)=A9)*N(+'B&B апрель 2025'!$L$2:$L$1311)) -> 305.85523 | D9: =C9-B9 -> 21.558079
A10: Прачечная 2 эт | B10: =SUMPRODUCT((TRIM('B&B апрель 2025'!$A$2:$A$1311)=A10)*N(+'B&B апрель 2025'!$H$2:$H$1311)) -> 291.5417 | C10: =SUMPRODUCT((TRIM('B&B апрель 2025'!$A$2:$A$1311)=A10)*N(+'B&B апрель 2025'!$L$2:$L$1311)) -> 310.91936 | D10: =C10-B10 -> 19.377663
A11: Коридор 2 эт - ванная | B11: =SUMPRODUCT((TRIM('B&B апрель 2025'!$A$2:$A$1311)=A11)*N(+'B&B апрель 2025'!$H$2:$H$1311)) -> 161.1811 | C11: =SUMPRODUCT((TRIM('B&B апрель 2025'!$A$2:$A$1311)=A11)*N(+'B&B апрель 2025'!$L$2:$L$1311)) -> 164.76688 | D11: =C11-B11 -> 3.5857789
A12: Ванная 2 эт | B12: =SUMPRODUCT((TRIM('B&B апрель 2025'!$A$2:$A$1311)=A12)*N(+'B&B апрель 2025'!$H$2:$H$1311)) -> 0 | C12: =SUMPRODUCT((TRIM('B&B апрель 2025'!$A$2:$A$1311)=A12)*N(+'B&B апрель 2025'!$L$2:$L$1311)) -> 0 | D12: =C12-B12 -> 0
A13: Коридор 2 эт - потолок | B13: =SUMPRODUCT((TRIM('B&B апрель 2025'!$A$2:$A$1311)=A13)*N(+'B&B апрель 2025'!$H$2:$H$1311)) -> 361.89938 | C13: =SUMPRODUCT((TRIM('B&B апрель 2025'!$A$2:$A$1311)=A13)*N(+'B&B апрель 2025'!$L$2:$L$1311)) -> 395.53702 | D13: =C13-B13 -> 33.637643
... A41: Подвал, лестница | B41: =SUMPRODUCT((TRIM('B&B апрель 2025'!$A$2:$A$1311)=A41)*N(+'B&B апрель 2025'!$H$2:$H$1311)) -> 0 | C41: =SUMPRODUCT((TRIM('B&B апрель 2025'!$A$2:$A$1311)=A41)*N(+'B&B апрель 2025'!$L$2:$L$1311)) -> 0 | D41: =C41-B41 -> 0
A42: ВСЕГО, $ | B42: =SUM('B&B апрель 2025'!$H$2:$H$1311) -> 7533.9025 | C42: =SUM('B&B апрель 2025'!$L$2:$L$1311) -> 8026.8151 | D42: =C42-B42 -> 492.91261
A44: Оплачено, $ (лист «Платежи») | B44: =Платежи!C17 -> 11465.88 | C44: =B44 -> 11465.88
A45: Баланс: работы − оплата, $ | B45: =B42-B44 -> -3931.9775 | C45: =C42-C44 -> -3439.0649
A46: Примечание: без разовых работ и без 14 строк без расценки

Sheet Аудит
A1: Помещение | B1: Поверхность | C1: Грунтовка, м2 | D1: Покраска (1 слой), м2 | E1: Разница, м2 | F1: Статус | G1: Строки грунт | H1: Строки покраска
A2: Анин гардероб | B2: потолок | C2: 4.47 | D2: 4.47 | E2: 0 | F2: OK | G2: 11 | H2: 13
A3: Анин гардероб | B3: стены | C3: 18.56 | D3: 18.56 | E3: 0 | F3: OK | G3: 10 | H3: 12
A4: Анина спальня/ванная | B4: потолок | C4: 16.53 | D4: 16.53 | E4: 0 | F4: OK | G4: 24 | H4: 25
A5: Анина спальня/ванная | B5: стены | C5: 11 | D5: 11 | E5: 0 | F5: OK | G5: 18 | H5: 19
A6: Зал | B6: балка | C6: 2.05 | D6: 2.05 | E6: 0 | F6: OK | G6: 202 | H6: 203
A7: Зал | B7: потолок | C7: 24.36 | D7: 24.36 | E7: 0 | F7: OK | G7: 197 | H7: 198
A8: Зал | B8: стены | C8: 32.9 | D8: 32.9 | E8: 0 | F8: OK | G8: 187 | H8: 181
A9: Коридор 2 эт | B9: откосы | C9: 1.69 | D9: 1.69 | E9: 0 | F9: OK | G9: 134 | H9: 135
A10: Коридор 2 эт | B10: потолок | C10: 20.1 | D10: 20.1 | E10: 0 | F10: OK | G10: 102, 113 | H10: 104, 114
A11: Коридор 2 эт | B11: стены | C11: 44.17 | D11: 46.7 | E11: 2.53 | F11: РАСХОЖДЕНИЕ | G11: 103, 136, 139 | H11: 105, 143
A12: Кухня | B12: потолок | C12: 11.5 | D12: 11.5 | E12: 0 | F12: OK | G12: 280 | H12: 282
A13: Кухня | B13: стены | C13: 24.3 | D13: 0 | E13: -24.3 | F13: нет покраски | G13: 281
A14: Лестница 2 эт | B14: стены | C14: 62.13 | D14: 62.13 | E14: 0 | F14: OK | G14: 147, 156, 158, 163, 167 | H14: 148, 157, 159, 164, 168
A15: Мастер-спальня | B15: потолок | C15: 0 | D15: 21.17 | E15: 21.17 | F15: нет грунтовки | H15: 27
A16: Мастер-спальня | B16: стены | C16: 0 | D16: 43.35 | E16: 43.35 | F16: нет грунтовки | H16: 28
A17: Наташин кабинет | B17: стены | C17: 9.2 | D17: 9.24 | E17: 0.04 | F17: OK | G17: 271 | H17: 273
A18: Прачечная 1эт. | B18: стены | C18: 22.37 | D18: 22.37 | E18: 0 | F18: OK | G18: 283 | H18: 285
A19: Прачечная 2 эт | B19: потолок | C19: 1.3 | D19: 1.3 | E19: 0 | F19: OK | G19: 89 | H19: 93
A20: Прачечная 2 эт | B20: стены | C20: 19.38 | D20: 9.69 | E20: -9.69 | F20: РАСХОЖДЕНИЕ | G20: 88, 90 | H20: 91
A21: Сашина спальня | B21: стены | C21: 17.57 | D21: 17.57 | E21: 0 | F21: OK | G21: 116 | H21: 117
A22: Серёжина спальня | B22: потолок | C22: 1.18 | D22: 1.18 | E22: 0 | F22: OK | G22: 126 | H22: 128
A23: Серёжина спальня | B23: стены | C23: 6.45 | D23: 6.86 | E23: 0.41 | F23: РАСХОЖДЕНИЕ | G23: 125 | H23: 127
A24: Столовая | B24: откосы | C24: 0 | D24: 5.78 | E24: 5.78 | F24: нет грунтовки | H24: 316
A25: Столовая | B25: потолок | C25: 13.66 | D25: 0 | E25: -13.66 | F25: нет покраски | G25: 310, 311
A26: Столовая | B26: стены | C26: 12.9 | D26: 12.88 | E26: -0.02 | F26: OK | G26: 312 | H26: 313
A27: Тамбур | B27: потолок | C27: 3.1 | D27: 3.06 | E27: -0.04 | F27: OK | G27: 254 | H27: 255
A28: Тамбур | B28: стены | C28: 10.8 | D28: 10.79 | E28: -0.01 | F28: OK | G28: 250 | H28: 256
A29: Узкий коридор 1 эт | B29: балка | C29: 1.5 | D29: 1.5 | E29: 0 | F29: OK | G29: 242 | H29: 243
A30: Узкий коридор 1 эт | B30: стены | C30: 29.4 | D30: 29.41 | E30: 0.01 | F30: OK | G30: 240 | H30: 235
A31: Фойе 2 эт | B31: потолок | C31: 9.05 | D31: 9.05 | E31: 0 | F31: OK | G31: 71 | H31: 73
A32: Фойе 2 эт | B32: стены | C32: 17.56 | D32: 17.56 | E32: 0 | F32: OK | G32: 70 | H32: 72
A33: Холл перед кухней | B33: потолок | C33: 1.49 | D33: 1.49 | E33: 0 | F33: OK | G33: 261 | H33: 262
A34: Холл перед кухней | B34: стены | C34: 5.04 | D34: 5.04 | E34: 0 | F34: OK | G34: 263 | H34: 264
A35: Холл перед столовой | B35: балка | C35: 21.9 | D35: 21.85 | E35: -0.05 | F35: OK | G35: 295 | H35: 297
A36: Холл перед столовой | B36: потолок | C36: 5.1 | D36: 5.12 | E36: 0.02 | F36: OK | G36: 294 | H36: 296
A37: Часовня | B37: откосы | C37: 1.19 | D37: 1.19 | E37: 0 | F37: OK | G37: 39 | H37: 40
... A42: Широкий коридор 1 эт | B42: стены | C42: 19.8 | D42: 19.76 | E42: -0.04 | F42: OK | G42: 210 | H42: 213
A44: Детализация работ по помещениям
A45: Помещение | B45: Работа | C45: Ед. | D45: Объём | E45: Цена $ | F45: ×k | G45: Итого $ | H45: Строки
...

Sheet B&B апрель 2025
A1: Комната | B1: Описание работы | C1: Тип работы | D1: Ед. изм. | E1: Объём | F1: Мультиплик. | G1: ='Dups+ B&B Rates'!$D$1 -> Цена, $ | H1: Итого, $ | J1: Заметка | K1: Цена рынок, $ | L1: Итого рынок, $
A2: Анин гардероб | B2: Монтаж ГКЛ на стену ванной | C2: Монтаж ГКЛ листов на клей | D2: м2 | E2: =1.67*2.75-2.08*0.7 -> 3.1365 | F2: 1 | G2: ='Dups+ B&B Rates'!$I$7 -> 4 | H2: =G2*F2*E2 -> 12.546 | K2: =G2 -> 4 | L2: =K2*F2*E2 -> 12.546
A3: Анин гардероб | B3: Усиление ГКЛ на стене в гардеробе | C3: Устройство каркаса и монтаж ГКЛ с виброизол. лентой без утепл. | D3: м2 | E3: =2.37*2.7-0.66*2.04 -> 5.0526 | F3: 1 | G3: ='Dups+ B&B Rates'!$I$8 -> 8 | H3: =G3*F3*E3 -> 40.4208 | K3: =Рынок!$D$8 -> 10.644668 | L3: =K3*F3*E3 -> 53.783248
A4: Анин гардероб | B4: Устройство и монтаж потолка | C4: Устройство каркаса и монтаж ГКЛ с виброизол. лентой + утеплитель | D4: м2 | E4: =1.74*2.57 -> 4.4718 | F4: 1 | G4: ='Dups+ B&B Rates'!$I$9 -> 9 | H4: =G4*F4*E4 -> 40.2462 | K4: =Рынок!$D$9 -> 10.644668 | L4: =K4*F4*E4 -> 47.600825
A5: Анин гардероб | B5: Проклеивание швов ГКЛ армлентой | C5: Проклейка армирующей ленты на стыки ГКЛ (стен и потолка) | D5: м.п. | E5: =(1.74+2.57)*2+2.7*6+1.74*2 -> 28.3 | F5: 1 | G5: ='Dups+ B&B Rates'!$I$19 -> 2 | H5: =G5*F5*E5 -> 56.6 | K5: =G5 -> 2 | L5: =K5*F5*E5 -> 56.6
A6: Анин гардероб | B6: Выравнивание швов потолка | C6: Шпатлевка потолка | D6: м.п. | E6: =(1.74+2.57)*2+1.74*2 -> 12.1 | F6: 1 | G6: ='Dups+ B&B Rates'!$I$27 -> 4 | H6: =G6*F6*E6 -> 48.4 | J6: ед.изм.: в строке «м.п.», в расценке «м2» | K6: =G6 -> 4 | L6: =K6*F6*E6 -> 48.4
A7: Анин гардероб | B7: Выравнивание швов стен | C7: Шпатлевка стен | D7: м.п. | E7: =2.7*6+0.65*2 -> 17.5 | F7: 1 | G7: ='Dups+ B&B Rates'!$I$28 -> 3 | H7: =G7*F7*E7 -> 52.5 | J7: ед.изм.: в строке «м.п.», в расценке «м2» | K7: =G7 -> 3 | L7: =K7*F7*E7 -> 52.5
A8: Анин гардероб | B8: Формирование внешних углов (дверной проём) | C8: Формирование внешних углов | D8: м.п. | E8: =(2.04+0.66+2.04)*2 -> 9.48 | F8: 1 | G8: ='Dups+ B&B Rates'!$I$22 -> 2.5 | H8: =G8*F8*E8 -> 23.7 | K8: =G8 -> 2.5 | L8: =K8*F8*E8 -> 23.7
A9: Анин гардероб | B9: Дверной проём | C9: Устройство дверного откоса | D9: м.п. | E9: =E8/2 -> 4.74 | F9: 1 | J9: нет расценки: Устройство дверного откоса
A10: Анин гардероб | B10: Грунтование стен | C10: Грунтование стен в 1 слой | D10: м2 | E10: =E2+E3+(2.7*(1.74+2.1)) -> 18.5571 | F10: 1 | G10: ='Dups+ B&B Rates'!$I$3 -> 0.5 | H10: =G10*F10*E10 -> 9.27855 | K10: =Рынок!$D$3 -> 0.66529173 | L10: =K10*F10*E10 -> 12.345885
A11: Анин гардероб | B11: Грунтование потолка | C11: Грунтование стен в 1 слой | D11: м2 | E11: =1.74*2.57 -> 4.4718 | F11: 1 | G11: ='Dups+ B&B Rates'!$I$3 -> 0.5 | H11: =G11*F11*E11 -> 2.2359 | K11: =Рынок!$D$3 -> 0.66529173 | L11: =K11*F11*E11 -> 2.9750516
A12: Анин гардероб | B12: Покраска стен | C12: Покраска стен | D12: м2 | E12: =E10 -> 18.5571 | F12: 2 | G12: ='Dups+ B&B Rates'!$I$18 -> 1 | H12: =G12*F12*E12 -> 37.1142 | K12: =G12 -> 1 | L12: =K12*F12*E12 -> 37.1142
A13: Анин гардероб | B13: Покраска потолка | C13: Покраска потолка | D13: м2 | E13: =1.74*2.57 -> 4.4718 | F13: 2 | G13: ='Dups+ B&B Rates'!$I$17 -> 1.5 | H13: =G13*F13*E13 -> 13.4154 | K13: =G13 -> 1.5 | L13: =K13*F13*E13 -> 13.4154
A14: Анин гардероб | B14: Увеличение стены Аниной комн. на дерев. каркасе | C14: Устройство двухсторонней перегородок из ГКЛ на металлокаркасе с шумоизоляцией | D14: м2 | E14: =2.06*0.2 -> 0.412 | F14: 1 | G14: ='Dups+ B&B Rates'!$I$23 -> 15 | H14: =G14*F14*E14 -> 6.18 | K14: =G14 -> 15 | L14: =K14*F14*E14 -> 6.18
A15: Анина ванная | B15: Утепление потолка | C15: Утепление потолка | D15: м2 | E15: =2.08*1.68 -> 3.4944 | F15: 1 | J15: нет расценки: Утепление потолка
A16: Анина спальня | B16: Ремонт и покраска оконных откосов | C16: Ремонт оконных откосов | D16: шт. | E16: 1 | F16: 1 | G16: ='Dups+ B&B Rates'!$I$31 -> 15 | H16: =G16*F16*E16 -> 15 | K16: =G16 -> 15 | L16: =K16*F16*E16 -> 15
A17: Анина спальня | B17: Шпатлевание стен (восточная и часть зап. стен) | C17: Шпатлевка стен | D17: м2 | E17: =4*2.75 -> 11 | F17: 1 | G17: ='Dups+ B&B Rates'!$I$28 -> 3 | H17: =G17*F17*E17 -> 33 | K17: =G17 -> 3 | L17: =K17*F17*E17 -> 33
A18: Анина спальня | B18: Грунтовка стен (восточная и часть зап. стен) | C18: Грунтование стен в 1 слой | D18: м2 | E18: =E17 -> 11 | F18: 1 | G18: ='Dups+ B&B Rates'!$I$3 -> 0.5 | H18: =G18*F18*E18 -> 5.5 | K18: =Рынок!$D$3 -> 0.66529173 | L18: =K18*F18*E18 -> 7.318209
A19: Анина спальня | B19: Покраска стен (восточная и часть зап. стен) | C19: Покраска стен | D19: м2 | E19: =E18 -> 11 | F19: 2 | G19: ='Dups+ B&B Rates'!$I$18 -> 1 | H19: =G19*F19*E19 -> 22 | K19: =G19 -> 1 | L19: =K19*F19*E19 -> 22
A20: Анина спальня | B20: Монтаж потолочного плинтуса из пенопласта | C20: Монтаж потолочного плинтуса из пенопласта | D20: м.п. | E20: =(348+475)*2/100 -> 16.46 | F20: 1 | G20: ='Dups+ B&B Rates'!$I$11 -> 3 | H20: =G20*F20*E20 -> 49.38 | K20: =Рынок!$D$5 -> 3.3264587 | L20: =K20*F20*E20 -> 54.753509
A21: Анина спальня | B21: Покраска потолочного молдинга | C21: Покраска потолка | D21: м.п. | E21: =(348+475)*2/100 -> 16.46 | F21: 2 | G21: ='Dups+ B&B Rates'!$I$17 -> 1.5 | H21: =G21*F21*E21 -> 49.38 | J21: ед.изм.: в строке «м.п.», в расценке «м2» | K21: =G21 -> 1.5 | L21: =K21*F21*E21 -> 49.38
A22: Анина спальня | B22: Ремонт шва, отверстий под светильники | C22: Шпатлевка потолка | D22: м2 | E22: 1 | F22: 1 | G22: ='Dups+ B&B Rates'!$I$27 -> 4 | H22: =G22*F22*E22 -> 4 | K22: =G22 -> 4 | L22: =K22*F22*E22 -> 4
A23: Анина спальня | B23: Монтаж центр. молдинга под люстру | C23: Шпатлевка потолка | D23: шт. | E23: 1 | F23: 1 | G23: ='Dups+ B&B Rates'!$I$27 -> 4 | H23: =G23*F23*E23 -> 4 | J23: ед.изм.: в строке «шт.», в расценке «м2» | K23: =G23 -> 4 | L23: =K23*F23*E23 -> 4
A24: Анина спальня | B24: Грунтовка потолка | C24: Грунтование потолков в 1 слой | D24: м2 | E24: =3.48*4.75 -> 16.53 | F24: 1 | G24: ='Dups+ B&B Rates'!$I$3 -> 0.5 | H24: =G24*F24*E24 -> 8.265 | K24: =Рынок!$D$3 -> 0.66529173 | L24: =K24*F24*E24 -> 10.997272
A25: Анина спальня | B25: Покраска потолка | C25: Покраска потолка | D25: м2 | E25: =E24 -> 16.53 | F25: 2 | G25: ='Dups+ B&B Rates'!$I$17 -> 1.5 | H25: =G25*F25*E25 -> 49.59 | K25: =G25 -> 1.5 | L25: =K25*F25*E25 -> 49.59
A26: Анина спальня | B26: Заливка цементом конвектора | C26: Бетонирование участков пола | D26: м2 | E26: 1 | F26: 1 | G26: ='Dups+ B&B Rates'!$I$33 -> 5 | H26: =G26*F26*E26 -> 5 | K26: =G26 -> 5 | L26: =K26*F26*E26 -> 5
A27: Мастер-спальня | B27: Покраска потолка | C27: Покраска потолка | D27: м2 | E27: =0.63*2.4+(4.43*3.65)+(0.43*1.93)+(1.93*1.38) -> 21.1748 | F27: 1 | G27: ='Dups+ B&B Rates'!$I$17 -> 1.5 | H27: =G27*F27*E27 -> 31.7622 | K27: =G27 -> 1.5 | L27: =K27*F27*E27 -> 31.7622
A28: Мастер-спальня | B28: Покраска стен | C28: Покраска стен | D28: м2 | E28: =(0.42+0.33+1.86+0.65+0.46+1.27+1.77+0.67+3.15+2.02+0.62+1.48+0.75)*2.64+(1.13*0.62+(1.23*0.2+(1.92*0.25+(1.17*0.52+(0.88*0.6))))) -> 43.351 | F28: 2 | G28: ='Dups+ B&B Rates'!$I$18 -> 1 | H28: =G28*F28*E28 -> 86.702 | K28: =G28 -> 1 | L28: =K28*F28*E28 -> 86.702
A29: Мастер спальня | B29: Внешние углы в спальне | C29: Формирование внешних углов | D29: м.п. | E29: 3.8 | F29: 1 | G29: ='Dups+ B&B Rates'!$I$22 -> 2.5 | H29: =G29*F29*E29 -> 9.5 | K29: =G29 -> 2.5 | L29: =K29*F29*E29 -> 9.5
A30: Мастер-спальня | B30: Внешние углы + балка | C30: Формирование внешних углов | D30: м.п. | E30: =E29 -> 3.8 | F30: 1 | G30: ='Dups+ B&B Rates'!$I$22 -> 2.5 | H30: =G30*F30*E30 -> 9.5 | K30: =G30 -> 2.5 | L30: =K30*F30*E30 -> 9.5
A31: Мастер-спальня | B31: откос полукруглый | C31: Формирование откоса | D31: м.п. | E31: =1.8+1.3*2 -> 4.4 | F31: 1 | J31: нет расценки: Формирование откоса
A32: Мастер-спальня | B32: Ремонт и покраска оконных откосов | C32: Ремонт оконных откосов | D32: шт. | E32: 3 | F32: 1 | G32: ='Dups+ B&B Rates'!$I$31 -> 15 | H32: =G32*F32*E32 -> 45 | K32: =G32 -> 15 | L32: =K32*F32*E32 -> 45
A33: Мастер-спальня | B33: вент отверстия | C33: Формирование отверстий | D33: м.п. | E33: 2 | F33: 1 | J33: нет расценки: Формирование отверстий
A34: Часовня | B34: Демонтаж радиатора | C34: Демонтаж/монтаж радиаторов отопления | D34: шт. | E34: 1 | F34: 1 | G34: ='Dups+ B&B Rates'!$I$4 -> 5 | H34: =G34*F34*E34 -> 5 | K34: =Рынок!$D$4 -> 13.305835 | L34: =K34*F34*E34 -> 13.305835
A35: Часовня | B35: Прокладка кабеля для "коморки" и для нижнего подключения | D35: шт. | E35: 1 | F35: 1 | J35: разовая работа — считаем позже
A36: Часовня | B36: Монтаж пенопл. утеплителя на внешнюю стену и под крышу | D36: м2 | E36: =1.75*0.75+0.84*0.65+0.92*0.48/2+0.2*0.78 -> 2.2353 | F36: 1.5 | J36: разовая работа — считаем позже
A37: Часовня | B37: Монтаж цементно-волокнистой плиты | C37: Устройство каркаса и монтаж ГКЛ с виброизол. лентой без утепл. | D37: м2 | E37: =1.5*1.9 -> 2.85 | F37: 1 | G37: ='Dups+ B&B Rates'!$I$8 -> 8 | H37: =G37*F37*E37 -> 22.8 | K37: =Рынок!$D$8 -> 10.644668 | L37: =K37*F37*E37 -> 30.337303
A38: Часовня | B38: Формирование округлого оконного проёма | C38: Облицовка оконных откосов гипсокартоном | D38: м.п. | E38: =4.75 -> 4.75 | F38: 1 | G38: ='Dups+ B&B Rates'!$I$12 -> 10 | H38: =G38*F38*E38 -> 47.5 | K38: =G38 -> 10 | L38: =K38*F38*E38 -> 47.5
A39: Часовня | B39: Грунтование округлого оконного проёма | C39: Грунтование стен в 1 слой | D39: м2 | E39: =E38*0.25 -> 1.1875 | F39: 1 | G39: ='Dups+ B&B Rates'!$I$3 -> 0.5 | H39: =G39*F39*E39 -> 0.59375 | K39: =Рынок!$D$3 -> 0.66529173 | L39: =K39*F39*E39 -> 0.79003393
A40: Часовня | B40: Покраска округлого оконного проёма | C40: Покраска стен | D40: м2 | E40: =E39 -> 1.1875 | F40: 2 | G40: ='Dups+ B&B Rates'!$I$18 -> 1 | H40: =G40*F40*E40 -> 2.375 | K40: =G40 -> 1 | L40: =K40*F40*E40 -> 2.375
...

Sheet Dups+ B&B Rates
A1: Тип работы | B1: Тип работы обобщённый | D1: Цена, $ | G1: Тип работ | H1: Ед. изм. | I1: Цена, $
E2: Выравнивание нижнего потолка | F2: Шпатлевка потолка | G2: Герметизация швов и стыков акриловым герметиком | H2: м.п. | I2: 1.5
A3: балка из узкого коридора | B3: Формирование балки ГКЛ | C3: =VLOOKUP(B3,E$2:F$46,2,FALSE()) -> Устройство потолочны коробов для балок | D3: =VLOOKUP(C3,G$2:I$35,3,FALSE()) -> 6.5 | E3: Выравнивание светового проёма потолка | F3: Шпатлевка потолка | G3: Грунтование стен и потолков в 1 слой | H3: м2 | I3: 0.5
A4: Балка перед кухней | B4: Формирование балки ГКЛ | C4: =VLOOKUP(B4,E$2:F$46,2,FALSE()) -> Устройство потолочны коробов для балок | D4: =VLOOKUP(C4,G$2:I$35,3,FALSE()) -> 6.5 | E4: Выравнивание откосов в нишах | F4: Облицовка оконных откосов гипсокартоном | G4: Демонтаж/монтаж радиаторов отопления | H4: шт. | I4: 5
A5: Балка перед лестницей | B5: Формирование балки ГКЛ | C5: =VLOOKUP(B5,E$2:F$46,2,FALSE()) -> Устройство потолочны коробов для балок | D5: =VLOOKUP(C5,G$2:I$35,3,FALSE()) -> 6.5 | E5: Выравнивание проблемных швов | F5: Шпатлевка потолка | G5: Заделка штроб электрики | H5: м.п. | I5: 1
A6: Бетонирование. выхода на терассу | B6: Бетонирование участков пола | C6: =VLOOKUP(B6,E$2:F$46,2,FALSE()) -> Бетонирование участков пола | D6: =VLOOKUP(C6,G$2:I$35,3,FALSE()) -> 5 | E6: Выравнивание стены под покраску | F6: Шпатлевка стен | G6: Изготовление отверстия в ГКЛ для монтажа подрозетников | H6: шт. | I6: 0.5
A7: Внешние углы | B7: Формирование внешних углов | C7: =VLOOKUP(B7,E$2:F$46,2,FALSE()) -> Установка перфорированого угла | D7: =VLOOKUP(C7,G$2:I$35,3,FALSE()) -> 2.5 | E7: Выравнивание швов - на потолке | F7: Проклейка армирующей ленты на стыки ГКЛ и на примыкания стен и потолка | G7: Монтаж ГКЛ листов на клею | H7: м2 | I7: 4
A8: Внутренние углы | B8: Формирование внутренних углов | C8: =VLOOKUP(B8,E$2:F$46,2,FALSE()) -> Проклейка армирующей ленты на стыки ГКЛ и на примыкания стен и потолка | D8: =VLOOKUP(C8,G$2:I$35,3,FALSE()) -> 2 | E8: Выравнивание швов (rework and cover holstom) | F8: Шпатлевка стен | G8: Устройство каркаса и монтаж ГКЛ с виброизол. лентой без утепл. | H8: м2 | I8: 8
A9: Выравнивание нижнего потолка | B9: Шпатлевка потолка | C9: =VLOOKUP(B9,E$2:F$46,2,FALSE()) -> Шпатлевка потолка | D9: =VLOOKUP(C9,G$2:I$35,3,FALSE()) -> 4 | E9: Грунтовка потолка | F9: Грунтование стен и потолков в 1 слой | G9: Устройство каркаса и монтаж ГКЛ с виброизол. лентой + утеплитель | H9: м2 | I9: 9
A10: Выравнивание проблем. швов | B10: Выравнивание проблемных швов | C10: =VLOOKUP(B10,E$2:F$46,2,FALSE()) -> Шпатлевка потолка | D10: =VLOOKUP(C10,G$2:I$35,3,FALSE()) -> 4 | E10: Грунтовка стен | F10: Грунтование стен и потолков в 1 слой | G10: Монтаж канализации | H10: шт. | I10: 200
A11: Выравнивание светового проёма потолка | B11: Шпатлевка потолка | C11: =VLOOKUP(B11,E$2:F$46,2,FALSE()) -> Шпатлевка потолка | D11: =VLOOKUP(C11,G$2:I$35,3,FALSE()) -> 4 | E11: Монтаж ГКЛ на каркас с утеплителем | F11: Устройство каркаса и монтаж ГКЛ с виброизол. лентой + утеплитель | G11: Монтаж потолочного плинтуса из пенопласта | H11: м.п. | I11: 3
A12: Выравнивание стен узкий коридор | B12: Шпатлевка стен | C12: Шпатлевка стен | D12: =VLOOKUP(C12,G$2:I$35,3,FALSE()) -> 3 | E12: Монтаж ГКЛ на каркас - потолок | F12: Устройство каркаса и монтаж ГКЛ с виброизол. лентой без утепл. | G12: Облицовка оконных откосов гипсокартоном | H12: м.п. | I12: 10
A13: Выравнивание швов | B13: Выравнивание швов | C13: Шпатлевка стен | D13: =VLOOKUP(C13,G$2:I$35,3,FALSE()) -> 3 | E13: Монтаж ГКЛ на каркас + утеплитель (потолок) | F13: Устройство каркаса и монтаж ГКЛ с виброизол. лентой + утеплитель | G13: Опрессовка труб в ванной | H13: шт. | I13: 35
A14: Выравнивание швов (rework and cover holstom) | B14: Выравнивание швов (rework and cover holstom) | C14: Поклейка холста (стены) | D14: =VLOOKUP(C14,G$2:I$35,3,FALSE()) -> 2 | E14: Монтаж ГКЛ - стены | F14: Монтаж ГКЛ листов на клею | G14: Пайка ПП труб | H14: шт. | I14: 35
A15: Выравнивание швов потолка | B15: Выравнивание швов потолка | C15: Шпатлевка потолка | D15: =VLOOKUP(C15,G$2:I$35,3,FALSE()) -> 4 | E15: Монтаж канализации | F15: Монтаж канализации | G15: Поклейка холста (потолок) | H15: м2 | I15: 3
A16: Выравнивание швов стен | B16: Выравнивание швов стен | C16: Шпатлевка стен | D16: =VLOOKUP(C16,G$2:I$35,3,FALSE()) -> 3 | E16: Наклеивание холста на потолок | F16: Поклейка холста (потолок) | G16: Поклейка холста (стены) | H16: м2 | I16: 2
A17: Грунтование стен | B17: Грунтовка стен | C17: =VLOOKUP(B17,E$2:F$46,2,FALSE()) -> Грунтование стен и потолков в 1 слой | D17: =VLOOKUP(C17,G$2:I$35,3,FALSE()) -> 0.5 | E17: Опрессовка труб | F17: Опрессовка труб в ванной | G17: Покраска потолка 1 слой | H17: м2 | I17: 1.5
A18: Грунтовка внутреннего потолка | B18: Грунтовка потолка | C18: =VLOOKUP(B18,E$2:F$46,2,FALSE()) -> Грунтование стен и потолков в 1 слой | D18: =VLOOKUP(C18,G$2:I$35,3,FALSE()) -> 0.5 | E18: Переноска ГКЛ на вост. стену | G18: Покраска стен 1 слой | H18: м2 | I18: 1
A19: Грунтовка лестничной стены | B19: Грунтовка стен | C19: =VLOOKUP(B19,E$2:F$46,2,FALSE()) -> Грунтование стен и потолков в 1 слой | D19: =VLOOKUP(C19,G$2:I$35,3,FALSE()) -> 0.5 | E19: Переноска ГКЛ на зап. стену | G19: Проклейка армирующей ленты на стыки ГКЛ и на примыкания стен и потолка | H19: м.п. | I19: 2
A20: Грунтовка лестничных стен с краской | B20: Грунтовка стен | C20: =VLOOKUP(B20,E$2:F$46,2,FALSE()) -> Грунтование стен и потолков в 1 слой | D20: =VLOOKUP(C20,G$2:I$35,3,FALSE()) -> 0.5 | E20: Покраска потолка | F20: Покраска потолка 1 слой | G20: Укрывка окон | H20: шт. | I20: 3
A21: Грунтовка нижнего потолка | B21: Грунтовка потолка | C21: =VLOOKUP(B21,E$2:F$46,2,FALSE()) -> Грунтование стен и потолков в 1 слой | D21: =VLOOKUP(C21,G$2:I$35,3,FALSE()) -> 0.5 | E21: Покраска потолочного плинтуса из пенопласта | F21: Покраска потолка 1 слой | G21: Усиление дверного проёма деревянным брусом | H21: шт. | I21: 15
A22: Грунтовка стен | B22: Грунтовка стен | C22: =VLOOKUP(B22,E$2:F$46,2,FALSE()) -> Грунтование стен и потолков в 1 слой | D22: =VLOOKUP(C22,G$2:I$35,3,FALSE()) -> 0.5 | E22: Покраска стен | F22: Покраска стен 1 слой | G22: Установка перфорированого угла | H22: м.п. | I22: 2.5
A23: Грунтовка стен входа Нат. каб. и стол. шкафов | B23: Грунтовка стен | C23: =VLOOKUP(B23,E$2:F$46,2,FALSE()) -> Грунтование стен и потолков в 1 слой | D23: =VLOOKUP(C23,G$2:I$35,3,FALSE()) -> 0.5 | E23: Покраска стен 2й слой | F23: Покраска стен 1 слой | G23: Устройство двухсторонней перегородок из ГКЛ на металлокаркасе с шумоизоляцией | H23: м2 | I23: 15
A24: Грунтовка швов | B24: Грунтовка стен | C24: =VLOOKUP(B24,E$2:F$46,2,FALSE()) -> Грунтование стен и потолков в 1 слой | D24: =VLOOKUP(C24,G$2:I$35,3,FALSE()) -> 0.5 | E24: Ремонт оконных откосов | F24: Ремонт оконных откосов | G24: Устройство каскада прямолинейного сложного (2 и более уровней) из ГКЛ + вибролента | H24: м2 | I24: 11
A25: Закл. холстом внешней стены стол. шкафов | B25: Наклеивание холста на стену | C25: =VLOOKUP(B25,E$2:F$46,2,FALSE()) -> Поклейка холста (стены) | D25: =VLOOKUP(C25,G$2:I$35,3,FALSE()) -> 2 | E25: Сверление отверстий под свет + А/С | F25: Сверление тех. отверстий в потолке | G25: Устройство подвесного потолка из гипсокартона в одном уровне 1 слой | H25: м2 | I25: 7
A26: Закл. холстом отрезка стены с тупым углом | B26: Наклеивание холста на стену | C26: =VLOOKUP(B26,E$2:F$46,2,FALSE()) -> Поклейка холста (стены) | D26: =VLOOKUP(C26,G$2:I$35,3,FALSE()) -> 2 | E26: Сверление тех. отверстий в потолке | F26: Сверление тех. отверстий в потолке | G26: Устройство потолочны коробов для балок | H26: м.п. | I26: 6.5
A27: Закл. холстом стены корид. вход Н. кабинет | B27: Наклеивание холста на стену | C27: =VLOOKUP(B27,E$2:F$46,2,FALSE()) -> Поклейка холста (стены) | D27: =VLOOKUP(C27,G$2:I$35,3,FALSE()) -> 2 | E27: Спайка труб | F27: Пайка ПП труб | G27: Шпатлевка потолка | H27: м2 | I27: 4
A28: Заклеивание большой стены холстом | B28: Наклеивание холста на стену | C28: =VLOOKUP(B28,E$2:F$46,2,FALSE()) -> Поклейка холста (стены) | D28: =VLOOKUP(C28,G$2:I$35,3,FALSE()) -> 2 | E28: Установка опуска дверных проёмов | F28: Усиление дверного проёма деревянным брусом | G28: Шпатлевка стен | H28: м2 | I28: 3
A29: Заклеивание стены перегородки холстом | B29: Наклеивание холста на стену | C29: =VLOOKUP(B29,E$2:F$46,2,FALSE()) -> Поклейка холста (стены) | D29: =VLOOKUP(C29,G$2:I$35,3,FALSE()) -> 2 | E29: Устройство оконного откоса | F29: Облицовка оконных откосов гипсокартоном | G29: Штукатурка прямолинейных откосов и проемов | H29: м.п. | I29: 6
A30: Заклейка холстом внутреннего потолка | B30: Наклеивание холста на потолок | C30: =VLOOKUP(B30,E$2:F$46,2,FALSE()) -> Поклейка холста (потолок) | D30: =VLOOKUP(C30,G$2:I$35,3,FALSE()) -> 3 | E30: Формирование балки ГКЛ | F30: Устройство потолочны коробов для балок | G30: Сверление тех. отверстий в потолке | H30: шт. | I30: 0.5
A31: Заклейка холстом нижнего потолка | B31: Наклеивание холста на потолок | C31: =VLOOKUP(B31,E$2:F$46,2,FALSE()) -> Поклейка холста (потолок) | D31: =VLOOKUP(C31,G$2:I$35,3,FALSE()) -> 3 | E31: Формирование внешних углов | F31: Установка перфорированого угла | G31: Ремонт оконных откосов | H31: шт. | I31: 15
A32: Монтаж потолочного плинтуса из пенопласта | B32: Монтаж потолочного плинтуса из пенопласта | C32: =VLOOKUP(B32, $E$2:$F$46, 2, FALSE()) -> Монтаж потолочного плинтуса из пенопласта | D32: =VLOOKUP(C32,G$2:I$35,3,FALSE()) -> 3 | E32: Формирование внутренних углов | F32: Проклейка армирующей ленты на стыки ГКЛ и на примыкания стен и потолка | G32: Выравнивание верха стены в зале (10 см) | H32: м.п. | I32: 5
A33: Монтаж внутреннего потолка (ГКЛ) | B33: Устройство каскада прямолинейного сложного (2 и более уровней) из ГКЛ + вибролента | C33: Устройство каскада прямолинейного сложного (2 и более уровней) из ГКЛ + вибролента | D33: =VLOOKUP(C33,G$2:I$35,3,FALSE()) -> 11 | E33: Шпатлевание большой стены с холстом | F33: Шпатлевка стен | G33: Бетонирование участков пола | H33: м2 | I33: 5
A34: Монтаж ГКЛ на балку | B34: Формирование балки ГКЛ | C34: =VLOOKUP(B34,E$2:F$46,2,FALSE()) -> Устройство потолочны коробов для балок | D34: =VLOOKUP(C34,G$2:I$35,3,FALSE()) -> 6.5 | E34: Шпатлевание гаражного дверного проёма | F34: Штукатурка прямолинейных откосов и проемов | G34: Кладка перегородки из пеноблока | H34: м2 | I34: 15
A35: Монтаж ГКЛ на стены | B35: Монтаж ГКЛ - стены | C35: =VLOOKUP(B35,E$2:F$46,2,FALSE()) -> Монтаж ГКЛ листов на клею | D35: =VLOOKUP(C35,G$2:I$35,3,FALSE()) -> 4 | E35: Шпатлевание главного дверного проёма | F35: Штукатурка прямолинейных откосов и проемов | H35: Грунтовка
A36: Монтаж и окраска ГКЛ на проём камина | B36: Монтаж ГКЛ | C36: =F13 -> Устройство каркаса и монтаж ГКЛ с виброизол. лентой + утеплитель | D36: =VLOOKUP(C36,G$2:I$35,3,FALSE()) -> 9 | E36: Шпатлевание добавл. отрезка ГКЛ | F36: Шпатлевка стен | H36: за кв.м.
A37: Монтаж канализации ванная 1эт. + стояк | B37: Монтаж канализации | C37: =VLOOKUP(B37,E$2:F$46,2,FALSE()) -> Монтаж канализации | D37: =VLOOKUP(C37,G$2:I$35,3,FALSE()) -> 200 | E37: Шпатлевание стен | F37: Шпатлевка стен | H37: Итого метраж
A38: Монтаж лестничной стены | B38: Монтаж ГКЛ - стены | C38: =VLOOKUP(B38,E$2:F$46,2,FALSE()) -> Монтаж ГКЛ листов на клею | D38: =VLOOKUP(C38,G$2:I$35,3,FALSE()) -> 4 | E38: Шпатлевка потолка | F38: Шпатлевка потолка | H38: Канализация
A39: Монтаж нижнего потолка (ГКЛ) | B39: Устройство каскада прямолинейного сложного (2 и более уровней) из ГКЛ + вибролента | C39: Устройство каскада прямолинейного сложного (2 и более уровней) из ГКЛ + вибролента | D39: =VLOOKUP(C39,G$2:I$35,3,FALSE()) -> 11 | E39: Монтаж потолочного плинтуса из пенопласта | F39: Монтаж потолочного плинтуса из пенопласта | H39: Отдел. работы
A40: Монтаж потолка ГКЛ | B40: Монтаж ГКЛ - потолок | C40: =F12 -> Устройство каркаса и монтаж ГКЛ с виброизол. лентой без утепл. | D40: =VLOOKUP(C40,G$2:I$35,3,FALSE()) -> 8 | E40: Наклеивание холста на стену | F40: Поклейка холста (стены) | H40: площадь
...

Sheet Платежи
A1: Date | B1: Amt BYN | C1: Amt USD | D1: for BYN to USD Conversion, use https://myfin.by/currency/usd | E1: Курс НБРБ (BYN за 1 USD) | F1: Источник: api.nbrb.by, официальный курс на дату платежа (из сводки HTML)
A2: 45587 | B2: 3000 | C2: =ROUND(B2/E2,2) -> 912.1 | E2: 3.2891
A3: 45597 | B3: 3000 | C3: =ROUND(B3/E3,2) -> 904.65 | E3: 3.3162
A4: 45618 | B4: 1000 | C4: =ROUND(B4/E4,2) -> 292.83 | E4: 3.415
A5: 45636 | B5: 2100 | C5: =ROUND(B5/E5,2) -> 621.76 | E5: 3.3775
A6: 45646 | B6: 3000 | C6: =ROUND(B6/E6,2) -> 864.06 | E6: 3.472
A7: 45654 | B7: 1500 | C7: =ROUND(B7/E7,2) -> 440.27 | E7: 3.407
A8: 45667 | B8: 3150 | C8: =ROUND(B8/E8,2) -> 904.68 | E8: 3.4819
A9: 45691 | B9: 1500 | C9: =ROUND(B9/E9,2) -> 441.14 | E9: 3.4003
A10: 45698 | B10: 4200 | C10: =ROUND(B10/E10,2) -> 1238.97 | E10: 3.3899
A11: 45715 | B11: 3000 | C11: =ROUND(B11/E11,2) -> 954.5 | E11: 3.143
A12: 45725 | B12: 3000 | C12: =ROUND(B12/E12,2) -> 927.5 | E12: 3.2345
A13: 45751 | B13: 300 | C13: =ROUND(B13/E13,2) -> 95.97 | E13: 3.1261
... A16: 45773 | B16: 900 | C16: =ROUND(B16/E16,2) -> 294.57 | E16: 3.0553
B17: =SUM(B2:B16) -> 37750 | C17: =SUM(C2:C16) -> 11465.88

Sheet Рынок
A1: Курс НБРБ, BYN за 1 USD (10.05.2025) | B1: 3.0062
A2: Тип работ (наш прайс) | B2: Ед. | C2: Наш прайс, $ | D2: Рыночная цена, $ (среднее по сайтам) | E2: Сайты и цены, BYN | F2: Сопоставление (наименование на сайте) | G2: Manhattan L1 | H2: Сходство | I2: Уверенность
A3: Грунтование стен и потолков в 1 слой | B3: м2 | C3: 0.5 | D3: =(2)/1/$B$1 -> 0.66529173 | E3: luxstroy.by: 2 | F3: грунтовка стен 1 слой | G3: 1 | H3: 0.86 | I3: Высокая
A4: Демонтаж/монтаж радиаторов отопления | B4: шт. | C4: 5 | D4: =(40)/1/$B$1 -> 13.305835 | E4: remontnik-minsk.by: 40 | F4: Демонтаж радиатора отопления (с сохранением) | G4: 2 | H4: 0.75 | I4: Высокая
A5: Монтаж потолочного плинтуса из пенопласта | B5: м.п. | C5: 3 | D5: =(10)/1/$B$1 -> 3.3264587 | E5: luxstroy.by: 10 | F5: монтаж плинтуса потолочного шириной до 5 см | G5: 3 | H5: 0.67 | I5: Высокая
A6: Устройство подвесного потолка из гипсокартона в одном уровне 1 слой | B6: м2 | C6: 7 | D6: =(30)/1/$B$1 -> 9.979376 | E6: luxstroy.by: 30 | F6: Устройство потолка из гипсокартона | G6: 4 | H6: 0.60 | I6: Высокая
A7: Устройство потолочны коробов для балок | B7: м.п. | C7: 6.5 | D7: =(25)/1/$B$1 -> 8.3161466 | E7: luxstroy.by: 25 | F7: устройство скрытых подсветок, коробов из ГКЛ | G7: 5 | H7: 0.44 | I7: Проверить
A8: Устройство каркаса и монтаж ГКЛ с виброизол. лентой без утепл. | B8: м2 | C8: 8 | D8: =(32)/1/$B$1 -> 10.644668 | E8: luxstroy.by: 32 | F8: монтаж гипсокартона по металлическому каркасу в 1 слой | G8: 8 | H8: 0.33 | I8: Проверить
A9: Устройство каркаса и монтаж ГКЛ с виброизол. лентой + утеплитель | B9: м2 | C9: 9 | D9: =(32)/1/$B$1 -> 10.644668 | E9: luxstroy.by: 32 | F9: монтаж гипсокартона по металлическому каркасу в 1 слой | G9: 8 | H9: 0.33 | I9: Проверить
A10: Поклейка холста (потолок) | B10: м2 | C10: 3 | D10: =(12+14)/2/$B$1 -> 4.3243962 | E10: remontnik-minsk.by: 12; luxstroy.by: 14 | F10: Поклейка обоев; поклейка обоев | G10: 3; 3 | H10: 0.40; 0.40 | I10: Проверить; Проверить
A11: Поклейка холста (стены) | B11: м2 | C11: 2 | D11: =(12+14)/2/$B$1 -> 4.3243962 | E11: remontnik-minsk.by: 12; luxstroy.by: 14 | F11: Поклейка обоев; поклейка обоев | G11: 3; 3 | H11: 0.40; 0.40 | I11: Проверить; Проверить
A12: Изготовление отверстия в ГКЛ для монтажа подрозетников | B12: шт. | C12: 0.5 | D12: =(10)/1/$B$1 -> 3.3264587 | E12: luxstroy.by: 10 | F12: Штробление и монтаж подрозетника | G12: 4 | H12: 0.50 | I12: Проверить
A14: Курс и допущения: luxstroy.by — валюта на странице не указана, принято BYN; remontnik-minsk.by «руб.» принято как BYN; сайты дают цены «под ключ мастера», у нас ставки подрядчика.
